Workbook

Sheet Velocidad
A1: Mes | B1: nombre | C1: tiendaf | D1: llave | E1: Cumplimiento | F1: Unid x Minuto
A2: enero | B2: Chiclayo - PVH | C2: =VLOOKUP(B2, tienda!A:D,4,0) -> P102 Chiclayo - PVH | D2: =C2&A2 -> P102 Chiclayo - PVHenero | E2: 0.9184 | F2: 12.86
A3: febrero | B3: Chiclayo - PVH | C3: =VLOOKUP(B3, tienda!A:D,4,0) -> P102 Chiclayo - PVH | D3: =C3&A3 -> P102 Chiclayo - PVHfebrero | E3: 0.9456 | F3: 13.24
A4: marzo | B4: Chiclayo - PVH | C4: =VLOOKUP(B4, tienda!A:D,4,0) -> P102 Chiclayo - PVH | D4: =C4&A4 -> P102 Chiclayo - PVHmarzo | E4: 1.0594 | F4: 14.83
A5: abril | B5: Chiclayo - PVH | C5: =VLOOKUP(B5, tienda!A:D,4,0) -> P102 Chiclayo - PVH | D5: =C5&A5 -> P102 Chiclayo - PVHabril | E5: 1.1746 | F5: 16.45
A6: mayo | B6: Chiclayo - PVH | C6: =VLOOKUP(B6, tienda!A:D,4,0) -> P102 Chiclayo - PVH | D6: =C6&A6 -> P102 Chiclayo - PVHmayo | E6: 1.1166 | F6: 15.63
A7: junio | B7: Chiclayo - PVH | C7: =VLOOKUP(B7, tienda!A:D,4,0) -> P102 Chiclayo - PVH | D7: =C7&A7 -> P102 Chiclayo - PVHjunio | E7: 0.9569 | F7: 13.4
A8: enero | B8: Chiclayo Aventura - PVH | C8: =VLOOKUP(B8, tienda!A:D,4,0) -> P769 Chiclayo Aventura - PVH | D8: =C8&A8 -> P769 Chiclayo Aventura - PVHenero | E8: 0.8509 | F8: 11.91
A9: febrero | B9: Chiclayo Aventura - PVH | C9: =VLOOKUP(B9, tienda!A:D,4,0) -> P769 Chiclayo Aventura - PVH | D9: =C9&A9 -> P769 Chiclayo Aventura - PVHfebrero | E9: 0.8821 | F9: 12.35
A10: marzo | B10: Chiclayo Aventura - PVH | C10: =VLOOKUP(B10, tienda!A:D,4,0) -> P769 Chiclayo Aventura - PVH | D10: =C10&A10 -> P769 Chiclayo Aventura - PVHmarzo | E10: 0.931 | F10: 13.03
A11: abril | B11: Chiclayo Aventura - PVH | C11: =VLOOKUP(B11, tienda!A:D,4,0) -> P769 Chiclayo Aventura - PVH | D11: =C11&A11 -> P769 Chiclayo Aventura - PVHabril | E11: 1.0396 | F11: 14.55
A12: mayo | B12: Chiclayo Aventura - PVH | C12: =VLOOKUP(B12, tienda!A:D,4,0) -> P769 Chiclayo Aventura - PVH | D12: =C12&A12 -> P769 Chiclayo Aventura - PVHmayo | E12: 0.9771 | F12: 13.68
A13: junio | B13: Chiclayo Aventura - PVH | C13: =VLOOKUP(B13, tienda!A:D,4,0) -> P769 Chiclayo Aventura - PVH | D13: =C13&A13 -> P769 Chiclayo Aventura - PVHjunio | E13: 1.0694 | F13: 14.97
... A67: junio | B67: Tumbes - PVH | C67: =VLOOKUP(B67, tienda!A:D,4,0) -> P724 Tumbes - PVH | D67: =C67&A67 -> P724 Tumbes - PVHjunio | E67: 1.0423 | F67: 14.59

Sheet Cobertura
A1: nombre | B1: tiendaf | C1: Mes | D1: llave | E1: Cobertura teórica | F1: MINCajas abiertas_marcaciones_real necesario | G1: Cobertura apoyo | H1: Efectividad pronóstico
A2: Chiclayo - PVH | B2: =VLOOKUP(A2, tienda!C:D,2,0) -> P102 Chiclayo - PVH | C2: enero | D2: =B2&C2 -> P102 Chiclayo - PVHenero | E2: 1.41 | F2: 1.31 | G2: 1.38 | H2: 1.02
A3: Chiclayo Aventura - PVH | B3: =VLOOKUP(A3, tienda!C:D,2,0) -> P769 Chiclayo Aventura - PVH | C3: enero | D3: =B3&C3 -> P769 Chiclayo Aventura - PVHenero | E3: 0.86 | F3: 1.02 | G3: 1.11 | H3: 1.31
A4: Chimbote - PVH | B4: =VLOOKUP(A4, tienda!C:D,2,0) -> P130 Chimbote - PVH | C4: enero | D4: =B4&C4 -> P130 Chimbote - PVHenero | E4: 1.37 | F4: 1.29 | G4: 1.33 | H4: 1.04
A5: El Chacarero - PVH | B5: =VLOOKUP(A5, tienda!C:D,2,0) -> P123 El Chacarero - PVH | C5: enero | D5: =B5&C5 -> P123 El Chacarero - PVHenero | E5: 0.91 | F5: 0.9 | G5: 1.42 | H5: 1.06
A6: Nvo Chimbote - PVH | B6: =VLOOKUP(A6, tienda!C:D,2,0) -> P143 Nvo Chimbote - PVH | C6: enero | D6: =B6&C6 -> P143 Nvo Chimbote - PVHenero | E6: 0.72 | F6: 1.21 | G6: 1.46 | H6: 1.3
A7: Paita - PVH | B7: =VLOOKUP(A7, tienda!C:D,2,0) -> P226 Paita - PVH | C7: enero | D7: =B7&C7 -> P226 Paita - PVHenero | E7: 1.22 | F7: 1.32 | G7: 1.41 | H7: 1.1
A8: Piura - PVH | B8: =VLOOKUP(A8, tienda!C:D,2,0) -> P145 Piura - PVH | C8: enero | D8: =B8&C8 -> P145 Piura - PVHenero | E8: 0.92 | F8: 0.87 | G8: 0.87 | H8: 1.12
A9: Sullana - PVH | B9: =VLOOKUP(A9, tienda!C:D,2,0) -> P192 Sullana - PVH | C9: enero | D9: =B9&C9 -> P192 Sullana - PVHenero | E9: 1.13 | F9: 1.16 | G9: 1.16 | H9: 1.08
A10: Talara - PVH | B10: =VLOOKUP(A10, tienda!C:D,2,0) -> P177 Talara - PVH | C10: enero | D10: =B10&C10 -> P177 Talara - PVHenero | E10: 1.26 | F10: 1.41 | G10: 1.41 | H10: 1.21
A11: Talara Municipalidad - PVH | B11: =VLOOKUP(A11, tienda!C:D,2,0) -> P262 Talara Municipalidad - PVH | C11: enero | D11: =B11&C11 -> P262 Talara Municipalidad - PVHenero | E11: 1.12 | F11: 1.08 | G11: 1.25 | H11: 1.15
A12: Tumbes - PVH | B12: =VLOOKUP(A12, tienda!C:D,2,0) -> P724 Tumbes - PVH | C12: enero | D12: =B12&C12 -> P724 Tumbes - PVHenero | E12: 0.92 | F12: 1.21 | G12: 1.21 | H12: 1.33
A13: Chiclayo - PVH | B13: =VLOOKUP(A13, tienda!C:D,2,0) -> P102 Chiclayo - PVH | C13: febrero | D13: =B13&C13 -> P102 Chiclayo - PVHfebrero | E13: 1.39 | F13: 1.2 | G13: 1.26 | H13: 0.93
... A67: Tumbes - PVH | B67: =VLOOKUP(A67, tienda!C:D,2,0) -> P724 Tumbes - PVH | C67: junio | D67: =B67&C67 -> P724 Tumbes - PVHjunio | E67: 0.67 | F67: 0.92 | G67: 0.98 | H67: 1.18

Sheet tienda
A1: Velocidad | B1: Productividad | C1: Cobertura | D1: final
A2: Chiclayo - PVH | B2: P102 Chiclayo - PVH | C2: Chiclayo - PVH | D2: P102 Chiclayo - PVH
A3: Chiclayo Aventura - PVH | B3: P769 Chiclayo Aventura - PVH | C3: Chiclayo Aventura - PVH | D3: P769 Chiclayo Aventura - PVH
A4: Chimbote - PVH | B4: P130 Chimbote - PVH | C4: Chimbote - PVH | D4: P130 Chimbote - PVH
A5: El Chacarero - PVH | B5: P123 El Chacarero - PVH | C5: El Chacarero - PVH | D5: P123 El Chacarero - PVH
A6: Nvo Chimbote - PVH | B6: P143 Nvo Chimbote - PVH | C6: Nvo Chimbote - PVH | D6: P143 Nvo Chimbote - PVH
A7: Paita - PVH | B7: P226 Paita - PVH | C7: Paita - PVH | D7: P226 Paita - PVH
A8: Piura - PVH | B8: P145 Piura - PVH | C8: Piura - PVH | D8: P145 Piura - PVH
A9: Sullana - PVH | B9: P192 Sullana - PVH | C9: Sullana - PVH | D9: P192 Sullana - PVH
A10: Talara - PVH | B10: P177 Talara - PVH | C10: Talara - PVH | D10: P177 Talara - PVH
A11: Talara Municipalidad - PVH | B11: P262 Talara Municipalidad - PVH | C11: Talara Municipalidad - PVH | D11: P262 Talara Municipalidad - PVH
A12: Tumbes - PVH | B12: P724 Tumbes - PVH | C12: Tumbes - PVH | D12: P724 Tumbes - PVH

Sheet Resumen
B1: ZONA GOR M.A.
B3: CUMPLIMIENTO DE VELOCIDAD
B4: Suma de Cumplimiento Velocidad | C4: Etiquetas de columna
B5: Tiendas | C5: ene | D5: feb | E5: mar | F5: abr | G5: may | H5: jun
B6: P102 Chiclayo - PVH | C6: 0.9184 | D6: 0.9456 | E6: 1.0594 | F6: 1.1746 | G6: 1.1166 | H6: 0.9569 | I6: revsiar el dash
B7: P123 El Chacarero - PVH | C7: 0.983 | D7: 1.0504 | E7: 1.0994 | F7: 1.0416 | G7: 1.0296 | H7: 1.1263
B8: P130 Chimbote - PVH | C8: 0.8982 | D8: 0.9927 | E8: 1.0156 | F8: 1.0197 | G8: 1.0097 | H8: 0.9852
B9: P143 Nvo Chimbote - PVH | C9: 0.8077 | D9: 0.8804 | E9: 0.9627 | F9: 0.9574 | G9: 0.9704 | H9: 1.0163
B10: P145 Piura - PVH | C10: 0.9524 | D10: 0.9938 | E10: 1.0181 | F10: 1.0254 | G10: 1.053 | H10: 1.0767
B11: P177 Talara - PVH | C11: 0.8733 | D11: 0.8817 | E11: 0.8978 | F11: 0.9542 | G11: 0.8681 | H11: 0.8693
B12: P192 Sullana - PVH* | C12: 0.8712 | D12: 0.96 | E12: 0.854 | F12: 0.8323 | G12: 0.6982 | H12: 0.7829 | I12: revisar el tema de celular
B13: P226 Paita - PVH | C13: 1.0866 | D13: 1.1738 | E13: 1.1888 | F13: 1.1917 | G13: 1.1677 | H13: 1.1212
B14: P262 Talara Municipalidad - PVH | C14: 0.9973 | D14: 1.0185 | E14: 1.0303 | F14: 1.0073 | G14: 1.0221 | H14: 1.0372
B15: P724 Tumbes - PVH | C15: 0.916 | D15: 0.8881 | E15: 0.9549 | F15: 1.0503 | G15: 1.0312 | H15: 1.0423
B16: P769 Chiclayo Aventura - PVH | C16: 0.8509 | D16: 0.8821 | E16: 0.931 | F16: 1.0396 | G16: 0.9771 | H16: 1.0694
B18: CUMPLIMIENTO DE DOTACIÓN ÁCIDA
B19: Suma de Cobertura Acida | C19: Etiquetas de columna
B20: Etiquetas de fila | C20: ene | D20: feb | E20: mar | F20: abr | G20: may | H20: jun
B21: P102 Chiclayo - PVH | C21: 1.41 | D21: 1.39 | E21: 1.21 | F21: 1.18 | G21: 1.12 | H21: 1.15
B22: P123 El Chacarero - PVH | C22: 0.91 | D22: 0.92 | E22: 0.87 | F22: 0.81 | G22: 1.06 | H22: 1.15
B23: P130 Chimbote - PVH | C23: 1.37 | D23: 1.21 | E23: 1.19 | F23: 1.16 | G23: 1.27 | H23: 1.31
B24: P143 Nvo Chimbote - PVH | C24: 0.72 | D24: 0.84 | E24: 0.86 | F24: 0.83 | G24: 0.74 | H24: 0.61
B25: P145 Piura - PVH | C25: 0.92 | D25: 0.98 | E25: 1.01 | F25: 0.94 | G25: 0.85 | H25: 0.97
B26: P177 Talara - PVH | C26: 1.26 | D26: 1.27 | E26: 1.25 | F26: 1.16 | G26: 1.13 | H26: 1.2
B27: P192 Sullana - PVH* | C27: 1.13 | D27: 1.21 | E27: 1.09 | F27: 1.08 | G27: 1.12 | H27: 1.34
B28: P226 Paita - PVH | C28: 1.22 | D28: 1.2 | E28: 1.11 | F28: 1.03 | G28: 1.01 | H28: 1.08
B29: P262 Talara Municipalidad - PVH | C29: 1.12 | D29: 1.1 | E29: 1.04 | F29: 1.01 | G29: 0.97 | H29: 1
B30: P724 Tumbes - PVH | C30: 0.92 | D30: 0.98 | E30: 1.12 | F30: 0.81 | G30: 0.89 | H30: 0.67 | I30: revisar la programación, los cambios deberian continuar con las siguientes.
B31: P769 Chiclayo Aventura - PVH | C31: 0.86 | D31: 0.86 | E31: 0.6 | F31: 0.49 | G31: 0.46 | H31: 0.48
B33: CUMPLIMIENTO DE PRODUCTIVIDAD (CAJAS)
B34: Suma de Cump Produc | C34: Etiquetas de columna
B35: Tiendas | C35: ene | D35: feb | E35: mar | F35: abr | G35: may | H35: jun
B36: P102 Chiclayo - PVH | C36: 1.0368229 | D36: 1.1425245 | E36: 1.1178923 | F36: 1.2094769 | G36: 1.2111864 | H36: 1.237401
B37: P123 El Chacarero - PVH | C37: 1.260191 | D37: 1.5495465 | E37: 1.0900902 | F37: 1.2331487 | G37: 1.2064478 | H37: 1.4300588 | I37: Considerar los trabajadores de Trux
B38: P130 Chimbote - PVH | C38: 1.0563629 | D38: 1.3098881 | E38: 1.1388263 | F38: 1.0769807 | G38: 0.97357712 | H38: 1.0970839
B39: P143 Nvo Chimbote - PVH | C39: 0.98192013 | D39: 1.0746936 | E39: 1.0071435 | F39: 1.1490853 | G39: 1.2476525 | H39: 1.2274249
B40: P145 Piura - PVH | C40: 1.157903 | D40: 1.2609125 | E40: 0.98840518 | F40: 1.0539473 | G40: 0.9985327 | H40: 1.0280764
B41: P177 Talara - PVH | C41: 0.88445026 | D41: 1.0182517 | E41: 0.76920321 | F41: 0.97772743 | G41: 0.88175809 | H41: 0.84172403 | I41: Baja Venta
B42: P192 Sullana - PVH | C42: 0.88878657 | D42: 0.98763981 | E42: 0.90115973 | F42: 0.90957321 | G42: 0.83235677 | H42: 0.79350773 | I42: Baja Venta
B43: P226 Paita - PVH | C43: 0.68087357 | D43: 0.86853137 | E43: 0.83994841 | F43: 0.85332424 | G43: 0.84762124 | H43: 0.84120415 | I43: Revisar Meta Productividad/ composicion (venta pos)
...

Sheet Productividad
A1: Tienda | B1: tiendaf | C1: Periodo | D1: llave | E1: Prod | F1: VtaNeta | G1: JEq | H1: ProdMeta | I1: Cump Produc | J1: ProdAA | K1: Cumplimiento Velocidad | L1: Cobertura Acida | M1: Evaluación | O1: 🟢 Operación eficiente
A2: P226 Paita - PVH | B2: P226 Paita - PVH | C2: mar | D2: P226 Paita - PVHmarzo | E2: 447280.9 | F2: 6771893 | G2: 15.140134 | H2: 532509.97 | I2: 0.83994841 | J2: 354976.12 | K2: 1.1888 | L2: 1.11 | M2: =IF(AND(L2<90%,K2<95%),"🚨 Dotación crítica", IF(AND(L2<90%,I2>=100%),"🔴 Dotación insuficiente", IF(AND(L2>110%,I2<100%),"🟠 Sobredotada", IF(AND(I2<100%,L2>=90%,L2<=110%),"🟡 Baja demanda", IF(AND(I2>=100%,K2>=95%),"🟢 Operación eficiente", "🔵 Baja eficiencia"))))) -> 🟠 Sobredotada
A3: P226 Paita - PVH | B3: P226 Paita - PVH | C3: may | D3: P226 Paita - PVHmayo | E3: 401019.11 | F3: 5959858.1 | G3: 14.861781 | H3: 473111.2 | I3: 0.84762124 | J3: 349759.55 | K3: 1.1677 | L3: 1.01 | M3: =IF(AND(L3<90%,K3<95%),"🚨 Dotación crítica", IF(AND(L3<90%,I3>=100%),"🔴 Dotación insuficiente", IF(AND(L3>110%,I3<100%),"🟠 Sobredotada", IF(AND(I3<100%,L3>=90%,L3<=110%),"🟡 Baja demanda", IF(AND(I3>=100%,K3>=95%),"🟢 Operación eficiente", "🔵 Baja eficiencia"))))) -> 🟡 Baja demanda | R3: sobredotación respecto a la demanda real
A4: P226 Paita - PVH | B4: P226 Paita - PVH | C4: abr | D4: P226 Paita - PVHabril | E4: 387136.13 | F4: 5814204 | G4: 15.0185 | H4: 453679.99 | I4: 0.85332424 | J4: 331304.57 | K4: 1.1917 | L4: 1.03 | M4: =IF(AND(L4<90%,K4<95%),"🚨 Dotación crítica", IF(AND(L4<90%,I4>=100%),"🔴 Dotación insuficiente", IF(AND(L4>110%,I4<100%),"🟠 Sobredotada", IF(AND(I4<100%,L4>=90%,L4<=110%),"🟡 Baja demanda", IF(AND(I4>=100%,K4>=95%),"🟢 Operación eficiente", "🔵 Baja eficiencia"))))) -> 🟡 Baja demanda | R4: baja venta
A5: P226 Paita - PVH | B5: P226 Paita - PVH | C5: feb | D5: P226 Paita - PVHfebrero | E5: 373475.14 | F5: 5505432 | G5: 14.741094 | H5: 430007.66 | I5: 0.86853137 | J5: 310820.06 | K5: 1.1738 | L5: 1.2 | M5: =IF(AND(L5<90%,K5<95%),"🚨 Dotación crítica", IF(AND(L5<90%,I5>=100%),"🔴 Dotación insuficiente", IF(AND(L5>110%,I5<100%),"🟠 Sobredotada", IF(AND(I5<100%,L5>=90%,L5<=110%),"🟡 Baja demanda", IF(AND(I5>=100%,K5>=95%),"🟢 Operación eficiente", "🔵 Baja eficiencia"))))) -> 🟠 Sobredotada | R5: dotación insuficiente
A6: P226 Paita - PVH | B6: P226 Paita - PVH | C6: jun | D6: P226 Paita - PVHjunio | E6: 354320.73 | F6: 4994214.7 | G6: 14.095181 | H6: 421206.59 | I6: 0.84120415 | J6: 314428.88 | K6: 1.1212 | L6: 1.08 | M6: =IF(AND(L6<90%,K6<95%),"🚨 Dotación crítica", IF(AND(L6<90%,I6>=100%),"🔴 Dotación insuficiente", IF(AND(L6>110%,I6<100%),"🟠 Sobredotada", IF(AND(I6<100%,L6>=90%,L6<=110%),"🟡 Baja demanda", IF(AND(I6>=100%,K6>=95%),"🟢 Operación eficiente", "🔵 Baja eficiencia"))))) -> 🟡 Baja demanda | R6: Dotación al límite, cajero exigido
A7: P226 Paita - PVH | B7: P226 Paita - PVH | C7: ene | D7: P226 Paita - PVHenero | E7: 306673.24 | F7: 4786938.4 | G7: 15.609247 | H7: 450411.42 | I7: 0.68087357 | J7: 246021.57 | K7: 1.0866 | L7: 1.22 | M7: =IF(AND(L7<90%,K7<95%),"🚨 Dotación crítica", IF(AND(L7<90%,I7>=100%),"🔴 Dotación insuficiente", IF(AND(L7>110%,I7<100%),"🟠 Sobredotada", IF(AND(I7<100%,L7>=90%,L7<=110%),"🟡 Baja demanda", IF(AND(I7>=100%,K7>=95%),"🟢 Operación eficiente", "🔵 Baja eficiencia"))))) -> 🟠 Sobredotada
A8: P143 Nvo Chimbote - PVH | B8: P143 Nvo Chimbote - PVH | C8: may | D8: P143 Nvo Chimbote - PVHmayo | E8: 416990.93 | F8: 4774736.7 | G8: 11.450457 | H8: 334220.4 | I8: 1.2476525 | J8: 356048.97 | K8: 0.9704 | L8: 0.74 | M8: =IF(AND(L8<90%,K8<95%),"🚨 Dotación crítica", IF(AND(L8<90%,I8>=100%),"🔴 Dotación insuficiente", IF(AND(L8>110%,I8<100%),"🟠 Sobredotada", IF(AND(I8<100%,L8>=90%,L8<=110%),"🟡 Baja demanda", IF(AND(I8>=100%,K8>=95%),"🟢 Operación eficiente", "🔵 Baja eficiencia"))))) -> 🔴 Dotación insuficiente
A9: P143 Nvo Chimbote - PVH | B9: P143 Nvo Chimbote - PVH | C9: jun | D9: P143 Nvo Chimbote - PVHjunio | E9: 379059.22 | F9: 4322596.6 | G9: 11.403486 | H9: 308824.78 | I9: 1.2274249 | J9: 306500.74 | K9: 1.0163 | L9: 0.61 | M9: =IF(AND(L9<90%,K9<95%),"🚨 Dotación crítica", IF(AND(L9<90%,I9>=100%),"🔴 Dotación insuficiente", IF(AND(L9>110%,I9<100%),"🟠 Sobredotada", IF(AND(I9<100%,L9>=90%,L9<=110%),"🟡 Baja demanda", IF(AND(I9>=100%,K9>=95%),"🟢 Operación eficiente", "🔵 Baja eficiencia"))))) -> 🔴 Dotación insuficiente
A10: P143 Nvo Chimbote - PVH | B10: P143 Nvo Chimbote - PVH | C10: mar | D10: P143 Nvo Chimbote - PVHmarzo | E10: 378954.25 | F10: 5110116.6 | G10: 13.484785 | H10: 376266.38 | I10: 1.0071435 | J10: 407607.82 | K10: 0.9627 | L10: 0.86 | M10: =IF(AND(L10<90%,K10<95%),"🚨 Dotación crítica", IF(AND(L10<90%,I10>=100%),"🔴 Dotación insuficiente", IF(AND(L10>110%,I10<100%),"🟠 Sobredotada", IF(AND(I10<100%,L10>=90%,L10<=110%),"🟡 Baja demanda", IF(AND(I10>=100%,K10>=95%),"🟢 Operación eficiente", "🔵 Baja eficiencia"))))) -> 🔴 Dotación insuficiente
A11: P143 Nvo Chimbote - PVH | B11: P143 Nvo Chimbote - PVH | C11: abr | D11: P143 Nvo Chimbote - PVHabril | E11: 367082.32 | F11: 4671543.1 | G11: 12.726146 | H11: 319456.11 | I11: 1.1490853 | J11: 380688.73 | K11: 0.9574 | L11: 0.83 | M11: =IF(AND(L11<90%,K11<95%),"🚨 Dotación crítica", IF(AND(L11<90%,I11>=100%),"🔴 Dotación insuficiente", IF(AND(L11>110%,I11<100%),"🟠 Sobredotada", IF(AND(I11<100%,L11>=90%,L11<=110%),"🟡 Baja demanda", IF(AND(I11>=100%,K11>=95%),"🟢 Operación eficiente", "🔵 Baja eficiencia"))))) -> 🔴 Dotación insuficiente
A12: P143 Nvo Chimbote - PVH | B12: P143 Nvo Chimbote - PVH | C12: ene | D12: P143 Nvo Chimbote - PVHenero | E12: 331314.74 | F12: 4813874 | G12: 14.52961 | H12: 337415.16 | I12: 0.98192013 | J12: 348135.95 | K12: 0.8077 | L12: 0.72 | M12: =IF(AND(L12<90%,K12<95%),"🚨 Dotación crítica", IF(AND(L12<90%,I12>=100%),"🔴 Dotación insuficiente", IF(AND(L12>110%,I12<100%),"🟠 Sobredotada", IF(AND(I12<100%,L12>=90%,L12<=110%),"🟡 Baja demanda", IF(AND(I12>=100%,K12>=95%),"🟢 Operación eficiente", "🔵 Baja eficiencia"))))) -> 🚨 Dotación crítica
A13: P143 Nvo Chimbote - PVH | B13: P143 Nvo Chimbote - PVH | C13: feb | D13: P143 Nvo Chimbote - PVHfebrero | E13: 326244.16 | F13: 4467353 | G13: 13.693281 | H13: 303569.46 | I13: 1.0746936 | J13: 334210.87 | K13: 0.8804 | L13: 0.84 | M13: =IF(AND(L13<90%,K13<95%),"🚨 Dotación crítica", IF(AND(L13<90%,I13>=100%),"🔴 Dotación insuficiente", IF(AND(L13>110%,I13<100%),"🟠 Sobredotada", IF(AND(I13<100%,L13>=90%,L13<=110%),"🟡 Baja demanda", IF(AND(I13>=100%,K13>=95%),"🟢 Operación eficiente", "🔵 Baja eficiencia"))))) -> 🚨 Dotación crítica
A14: P262 Talara Municipalidad - PVH | B14: P262 Talara Municipalidad - PVH | C14: mar | D14: P262 Talara Municipalidad - PVHmarzo | E14: 379297.99 | F14: 5412467.6 | G14: 14.269698 | H14: 339251.76 | I14: 1.1180428 | J14: 322838.55 | K14: 1.0303 | L14: 1.04 | M14: =IF(AND(L14<90%,K14<95%),"🚨 Dotación crítica", IF(AND(L14<90%,I14>=100%),"🔴 Dotación insuficiente", IF(AND(L14>110%,I14<100%),"🟠 Sobredotada", IF(AND(I14<100%,L14>=90%,L14<=110%),"🟡 Baja demanda", IF(AND(I14>=100%,K14>=95%),"🟢 Operación eficiente", "🔵 Baja eficiencia"))))) -> 🟢 Operación eficiente
A15: P262 Talara Municipalidad - PVH | B15: P262 Talara Municipalidad - PVH | C15: may | D15: P262 Talara Municipalidad - PVHmayo | E15: 375166.85 | F15: 5282498 | G15: 14.080397 | H15: 330957.16 | I15: 1.1335813 | J15: 306649.42 | K15: 1.0221 | L15: 0.97 | M15: =IF(AND(L15<90%,K15<95%),"🚨 Dotación crítica", IF(AND(L15<90%,I15>=100%),"🔴 Dotación insuficiente", IF(AND(L15>110%,I15<100%),"🟠 Sobredotada", IF(AND(I15<100%,L15>=90%,L15<=110%),"🟡 Baja demanda", IF(AND(I15>=100%,K15>=95%),"🟢 Operación eficiente", "🔵 Baja eficiencia"))))) -> 🟢 Operación eficiente
A16: P262 Talara Municipalidad - PVH | B16: P262 Talara Municipalidad - PVH | C16: jun | D16: P262 Talara Municipalidad - PVHjunio | E16: 350452.98 | F16: 4884297.3 | G16: 13.937097 | H16: 289596.54 | I16: 1.2101422 | J16: 295775.79 | K16: 1.0372 | L16: 1 | M16: =IF(AND(L16<90%,K16<95%),"🚨 Dotación crítica", IF(AND(L16<90%,I16>=100%),"🔴 Dotación insuficiente", IF(AND(L16>110%,I16<100%),"🟠 Sobredotada", IF(AND(I16<100%,L16>=90%,L16<=110%),"🟡 Baja demanda", IF(AND(I16>=100%,K16>=95%),"🟢 Operación eficiente", "🔵 Baja eficiencia"))))) -> 🟢 Operación eficiente | O16: 1.1180428 | P16: 1.0303 | Q16: 1.04
A17: P262 Talara Municipalidad - PVH | B17: P262 Talara Municipalidad - PVH | C17: ene | D17: P262 Talara Municipalidad - PVHenero | E17: 345810.91 | F17: 4640670.9 | G17: 13.419677 | H17: 304857.9 | I17: 1.1343348 | J17: 278713.57 | K17: 0.9973 | L17: 1.12 | M17: =IF(AND(L17<90%,K17<95%),"🚨 Dotación crítica", IF(AND(L17<90%,I17>=100%),"🔴 Dotación insuficiente", IF(AND(L17>110%,I17<100%),"🟠 Sobredotada", IF(AND(I17<100%,L17>=90%,L17<=110%),"🟡 Baja demanda", IF(AND(I17>=100%,K17>=95%),"🟢 Operación eficiente", "🔵 Baja eficiencia"))))) -> 🟢 Operación eficiente | O17: 1.1335813 | P17: 1.0221 | Q17: 0.97
A18: P262 Talara Municipalidad - PVH | B18: P262 Talara Municipalidad - PVH | C18: abr | D18: P262 Talara Municipalidad - PVHabril | E18: 339699.43 | F18: 4657968 | G18: 13.712028 | H18: 310173.77 | I18: 1.0951907 | J18: 280640.97 | K18: 1.0073 | L18: 1.01 | M18: =IF(AND(L18<90%,K18<95%),"🚨 Dotación crítica", IF(AND(L18<90%,I18>=100%),"🔴 Dotación insuficiente", IF(AND(L18>110%,I18<100%),"🟠 Sobredotada", IF(AND(I18<100%,L18>=90%,L18<=110%),"🟡 Baja demanda", IF(AND(I18>=100%,K18>=95%),"🟢 Operación eficiente", "🔵 Baja eficiencia"))))) -> 🟢 Operación eficiente | O18: 1.2101422 | P18: 1.0372 | Q18: 1
A19: P262 Talara Municipalidad - PVH | B19: P262 Talara Municipalidad - PVH | C19: feb | D19: P262 Talara Municipalidad - PVHfebrero | E19: 339682.39 | F19: 4675462.8 | G19: 13.764219 | H19: 286467.5 | I19: 1.1857624 | J19: 252397.73 | K19: 1.0185 | L19: 1.1 | M19: =IF(AND(L19<90%,K19<95%),"🚨 Dotación crítica", IF(AND(L19<90%,I19>=100%),"🔴 Dotación insuficiente", IF(AND(L19>110%,I19<100%),"🟠 Sobredotada", IF(AND(I19<100%,L19>=90%,L19<=110%),"🟡 Baja demanda", IF(AND(I19>=100%,K19>=95%),"🟢 Operación eficiente", "🔵 Baja eficiencia"))))) -> 🟢 Operación eficiente | O19: 1.1343348 | P19: 0.9973 | Q19: 1.12
A20: P769 Chiclayo Aventura - PVH | B20: P769 Chiclayo Aventura - PVH | C20: mar | D20: P769 Chiclayo Aventura - PVHmarzo | E20: 408727.38 | F20: 6918765.6 | G20: 16.927581 | H20: 349555.91 | I20: 1.1692761 | J20: 407462.85 | K20: 0.931 | L20: 0.6 | M20: =IF(AND(L20<90%,K20<95%),"🚨 Dotación crítica", IF(AND(L20<90%,I20>=100%),"🔴 Dotación insuficiente", IF(AND(L20>110%,I20<100%),"🟠 Sobredotada", IF(AND(I20<100%,L20>=90%,L20<=110%),"🟡 Baja demanda", IF(AND(I20>=100%,K20>=95%),"🟢 Operación eficiente", "🔵 Baja eficiencia"))))) -> 🚨 Dotación crítica | O20: 1.0951907 | P20: 1.0073 | Q20: 1.01
A21: P769 Chiclayo Aventura - PVH | B21: P769 Chiclayo Aventura - PVH | C21: may | D21: P769 Chiclayo Aventura - PVHmayo | E21: 355813.95 | F21: 5888273.7 | G21: 16.548743 | H21: 294642.71 | I21: 1.2076116 | J21: 265182.15 | K21: 0.9771 | L21: 0.46 | M21: =IF(AND(L21<90%,K21<95%),"🚨 Dotación crítica", IF(AND(L21<90%,I21>=100%),"🔴 Dotación insuficiente", IF(AND(L21>110%,I21<100%),"🟠 Sobredotada", IF(AND(I21<100%,L21>=90%,L21<=110%),"🟡 Baja demanda", IF(AND(I21>=100%,K21>=95%),"🟢 Operación eficiente", "🔵 Baja eficiencia"))))) -> 🔴 Dotación insuficiente | O21: 1.1857624 | P21: 1.0185 | Q21: 1.1
A22: P769 Chiclayo Aventura - PVH | B22: P769 Chiclayo Aventura - PVH | C22: abr | D22: P769 Chiclayo Aventura - PVHabril | E22: 333715.73 | F22: 5343558.2 | G22: 16.012306 | H22: 281967.83 | I22: 1.1835241 | J22: 264628.37 | K22: 1.0396 | L22: 0.49 | M22: =IF(AND(L22<90%,K22<95%),"🚨 Dotación crítica", IF(AND(L22<90%,I22>=100%),"🔴 Dotación insuficiente", IF(AND(L22>110%,I22<100%),"🟠 Sobredotada", IF(AND(I22<100%,L22>=90%,L22<=110%),"🟡 Baja demanda", IF(AND(I22>=100%,K22>=95%),"🟢 Operación eficiente", "🔵 Baja eficiencia"))))) -> 🔴 Dotación insuficiente | O22: 1.1692761 | P22: 0.931 | Q22: 0.6
A23: P769 Chiclayo Aventura - PVH | B23: P769 Chiclayo Aventura - PVH | C23: feb | D23: P769 Chiclayo Aventura - PVHfebrero | E23: 314429.88 | F23: 5924972.6 | G23: 18.843542 | H23: 284114.67 | I23: 1.1067006 | J23: 275397.29 | K23: 0.8821 | L23: 0.86 | M23: =IF(AND(L23<90%,K23<95%),"🚨 Dotación crítica", IF(AND(L23<90%,I23>=100%),"🔴 Dotación insuficiente", IF(AND(L23>110%,I23<100%),"🟠 Sobredotada", IF(AND(I23<100%,L23>=90%,L23<=110%),"🟡 Baja demanda", IF(AND(I23>=100%,K23>=95%),"🟢 Operación eficiente", "🔵 Baja eficiencia"))))) -> 🚨 Dotación crítica | O23: 1.2076116 | P23: 0.9771 | Q23: 0.46
A24: P769 Chiclayo Aventura - PVH | B24: P769 Chiclayo Aventura - PVH | C24: jun | D24: P769 Chiclayo Aventura - PVHjunio | E24: 299725 | F24: 5024700.2 | G24: 16.764368 | H24: 255645.92 | I24: 1.1724224 | J24: 245081.17 | K24: 1.0694 | L24: 0.48 | M24: =IF(AND(L24<90%,K24<95%),"🚨 Dotación crítica", IF(AND(L24<90%,I24>=100%),"🔴 Dotación insuficiente", IF(AND(L24>110%,I24<100%),"🟠 Sobredotada", IF(AND(I24<100%,L24>=90%,L24<=110%),"🟡 Baja demanda", IF(AND(I24>=100%,K24>=95%),"🟢 Operación eficiente", "🔵 Baja eficiencia"))))) -> 🔴 Dotación insuficiente | O24: 1.1835241 | P24: 1.0396 | Q24: 0.49
A25: P769 Chiclayo Aventura - PVH | B25: P769 Chiclayo Aventura - PVH | C25: ene | D25: P769 Chiclayo Aventura - PVHenero | E25: 272846.96 | F25: 4917732.8 | G25: 18.023777 | H25: 289613.23 | I25: 0.94210809 | J25: 259013.64 | K25: 0.8509 | L25: 0.86 | M25: =IF(AND(L25<90%,K25<95%),"🚨 Dotación crítica", IF(AND(L25<90%,I25>=100%),"🔴 Dotación insuficiente", IF(AND(L25>110%,I25<100%),"🟠 Sobredotada", IF(AND(I25<100%,L25>=90%,L25<=110%),"🟡 Baja demanda", IF(AND(I25>=100%,K25>=95%),"🟢 Operación eficiente", "🔵 Baja eficiencia"))))) -> 🚨 Dotación crítica | O25: 1.1067006 | P25: 0.8821 | Q25: 0.86
A26: P102 Chiclayo - PVH | B26: P102 Chiclayo - PVH | C26: mar | D26: P102 Chiclayo - PVHmarzo | E26: 387601.63 | F26: 12185747 | G26: 31.438844 | H26: 346725.38 | I26: 1.1178923 | J26: 351341.81 | K26: 1.0594 | L26: 1.21 | M26: =IF(AND(L26<90%,K26<95%),"🚨 Dotación crítica", IF(AND(L26<90%,I26>=100%),"🔴 Dotación insuficiente", IF(AND(L26>110%,I26<100%),"🟠 Sobredotada", IF(AND(I26<100%,L26>=90%,L26<=110%),"🟡 Baja demanda", IF(AND(I26>=100%,K26>=95%),"🟢 Operación eficiente", "🔵 Baja eficiencia"))))) -> 🟢 Operación eficiente | O26: 1.1724224 | P26: 1.0694 | Q26: 0.48
A27: P102 Chiclayo - PVH | B27: P102 Chiclayo - PVH | C27: may | D27: P102 Chiclayo - PVHmayo | E27: 331870.01 | F27: 9750327.4 | G27: 29.37996 | H27: 274004.07 | I27: 1.2111864 | J27: 265493.47 | K27: 1.1166 | L27: 1.12 | M27: =IF(AND(L27<90%,K27<95%),"🚨 Dotación crítica", IF(AND(L27<90%,I27>=100%),"🔴 Dotación insuficiente", IF(AND(L27>110%,I27<100%),"🟠 Sobredotada", IF(AND(I27<100%,L27>=90%,L27<=110%),"🟡 Baja demanda", IF(AND(I27>=100%,K27>=95%),"🟢 Operación eficiente", "🔵 Baja eficiencia"))))) -> 🟢 Operación eficiente | O27: 0.94210809 | P27: 0.8509 | Q27: 0.86
A28: P102 Chiclayo - PVH | B28: P102 Chiclayo - PVH | C28: feb | D28: P102 Chiclayo - PVHfebrero | E28: 327628.55 | F28: 10250439 | G28: 31.286771 | H28: 286758.43 | I28: 1.1425245 | J28: 285726.69 | K28: 0.9456 | L28: 1.39 | M28: 🟢 Operación eficiente | O28: 1.1178923 | P28: 1.0594 | Q28: 1.21
A29: P102 Chiclayo - PVH | B29: P102 Chiclayo - PVH | C29: abr | D29: P102 Chiclayo - PVHabril | E29: 319268.46 | F29: 9496638.1 | G29: 29.744993 | H29: 263972.34 | I29: 1.2094769 | J29: 257242.99 | K29: 1.1746 | L29: 1.18 | M29: =IF(AND(L29<90%,K29<95%),"🚨 Dotación crítica", IF(AND(L29<90%,I29>=100%),"🔴 Dotación insuficiente", IF(AND(L29>110%,I29<100%),"🟠 Sobredotada", IF(AND(I29<100%,L29>=90%,L29<=110%),"🟡 Baja demanda", IF(AND(I29>=100%,K29>=95%),"🟢 Operación eficiente", "🔵 Baja eficiencia"))))) -> 🟢 Operación eficiente | O29: 1.2111864 | P29: 1.1166 | Q29: 1.12
A30: P102 Chiclayo - PVH | B30: P102 Chiclayo - PVH | C30: jun | D30: P102 Chiclayo - PVHjunio | E30: 311190.87 | F30: 8909001.2 | G30: 28.628736 | H30: 251487.48 | I30: 1.237401 | J30: 242457.4 | K30: 0.9569 | L30: 1.15 | M30: =IF(AND(L30<90%,K30<95%),"🚨 Dotación crítica", IF(AND(L30<90%,I30>=100%),"🔴 Dotación insuficiente", IF(AND(L30>110%,I30<100%),"🟠 Sobredotada", IF(AND(I30<100%,L30>=90%,L30<=110%),"🟡 Baja demanda", IF(AND(I30>=100%,K30>=95%),"🟢 Operación eficiente", "🔵 Baja eficiencia"))))) -> 🟢 Operación eficiente | O30: 1.1425245 | P30: 0.9456 | Q30: 1.39
A31: P102 Chiclayo - PVH | B31: P102 Chiclayo - PVH | C31: ene | D31: P102 Chiclayo - PVHenero | E31: 276111.91 | F31: 8889803.3 | G31: 32.196378 | H31: 266305.77 | I31: 1.0368229 | J31: 277111.46 | K31: 0.9184 | L31: 1.41 | M31: 🟠 Sobredotada | O31: 1.2094769 | P31: 1.1746 | Q31: 1.18
A32: P724 Tumbes - PVH | B32: P724 Tumbes - PVH | C32: may | D32: P724 Tumbes - PVHmayo | E32: 330149.08 | F32: 6417075.2 | G32: 19.436902 | H32: 360970.58 | I32: 0.91461491 | J32: 359897.94 | K32: 1.0312 | L32: 0.89 | M32: 🟡 Baja demanda | O32: 1.237401 | P32: 0.9569 | Q32: 1.15
A33: P724 Tumbes - PVH | B33: P724 Tumbes - PVH | C33: mar | D33: P724 Tumbes - PVHmarzo | E33: 329855.97 | F33: 6954425.7 | G33: 21.083219 | H33: 419910.48 | I33: 0.7855388 | J33: 428084.77 | K33: 0.9549 | L33: 1.12 | M33: =IF(AND(L33<90%,K33<95%),"🚨 Dotación crítica", IF(AND(L33<90%,I33>=100%),"🔴 Dotación insuficiente", IF(AND(L33>110%,I33<100%),"🟠 Sobredotada", IF(AND(I33<100%,L33>=90%,L33<=110%),"🟡 Baja demanda", IF(AND(I33>=100%,K33>=95%),"🟢 Operación eficiente", "🔵 Baja eficiencia"))))) -> 🟠 Sobredotada | O33: 1.0368229 | P33: 0.9184 | Q33: 1.41
A34: P724 Tumbes - PVH | B34: P724 Tumbes - PVH | C34: ene | D34: P724 Tumbes - PVHenero | E34: 326343.42 | F34: 6812896.9 | G34: 20.876465 | H34: 329126.12 | I34: 0.99154518 | J34: 374185.32 | K34: 0.916 | L34: 0.92 | M34: =IF(AND(L34<90%,K34<95%),"🚨 Dotación crítica", IF(AND(L34<90%,I34>=100%),"🔴 Dotación insuficiente", IF(AND(L34>110%,I34<100%),"🟠 Sobredotada", IF(AND(I34<100%,L34>=90%,L34<=110%),"🟡 Baja demanda", IF(AND(I34>=100%,K34>=95%),"🟢 Operación eficiente", "🔵 Baja eficiencia"))))) -> 🟡 Baja demanda | O34: 0.91461491 | P34: 1.0312 | Q34: 0.89
A35: P724 Tumbes - PVH | B35: P724 Tumbes - PVH | C35: abr | D35: P724 Tumbes - PVHabril | E35: 315519.62 | F35: 6247253.5 | G35: 19.799889 | H35: 359515.06 | I35: 0.8776256 | J35: 386130.4 | K35: 1.0503 | L35: 0.81 | M35: 🟡 Baja demanda | O35: 0.7855388 | P35: 0.9549 | Q35: 1.12
A36: P724 Tumbes - PVH | B36: P724 Tumbes - PVH | C36: feb | D36: P724 Tumbes - PVHfebrero | E36: 304354.48 | F36: 6341257.2 | G36: 20.835104 | H36: 323832.1 | I36: 0.93985272 | J36: 366733.81 | K36: 0.8881 | L36: 0.98 | M36: =IF(AND(L36<90%,K36<95%),"🚨 Dotación crítica", IF(AND(L36<90%,I36>=100%),"🔴 Dotación insuficiente", IF(AND(L36>110%,I36<100%),"🟠 Sobredotada", IF(AND(I36<100%,L36>=90%,L36<=110%),"🟡 Baja demanda", IF(AND(I36>=100%,K36>=95%),"🟢 Operación eficiente", "🔵 Baja eficiencia"))))) -> 🟡 Baja demanda | O36: 0.99154518 | P36: 0.916 | Q36: 0.92
A37: P724 Tumbes - PVH | B37: P724 Tumbes - PVH | C37: jun | D37: P724 Tumbes - PVHjunio | E37: 304303.16 | F37: 5361502.6 | G37: 17.618951 | H37: 318037.49 | I37: 0.95681538 | J37: 323179.38 | K37: 1.0423 | L37: 0.67 | M37: 🟡 Baja demanda | O37: 0.8776256 | P37: 1.0503 | Q37: 0.81
A38: P130 Chimbote - PVH | B38: P130 Chimbote - PVH | C38: mar | D38: P130 Chimbote - PVHmarzo | E38: 394997.64 | F38: 7065610.5 | G38: 17.887728 | H38: 346846.25 | I38: 1.1388263 | J38: 424540.26 | K38: 1.0156 | L38: 1.19 | M38: =IF(AND(L38<90%,K38<95%),"🚨 Dotación crítica", IF(AND(L38<90%,I38>=100%),"🔴 Dotación insuficiente", IF(AND(L38>110%,I38<100%),"🟠 Sobredotada", IF(AND(I38<100%,L38>=90%,L38<=110%),"🟡 Baja demanda", IF(AND(I38>=100%,K38>=95%),"🟢 Operación eficiente", "🔵 Baja eficiencia"))))) -> 🟢 Operación eficiente | O38: 0.93985272 | P38: 0.8881 | Q38: 0.98
A39: P130 Chimbote - PVH | B39: P130 Chimbote - PVH | C39: feb | D39: P130 Chimbote - PVHfebrero | E39: 352283.44 | F39: 5847483 | G39: 16.598802 | H39: 268941.64 | I39: 1.3098881 | J39: 310503.03 | K39: 0.9927 | L39: 1.21 | M39: =IF(AND(L39<90%,K39<95%),"🚨 Dotación crítica", IF(AND(L39<90%,I39>=100%),"🔴 Dotación insuficiente", IF(AND(L39>110%,I39<100%),"🟠 Sobredotada", IF(AND(I39<100%,L39>=90%,L39<=110%),"🟡 Baja demanda", IF(AND(I39>=100%,K39>=95%),"🟢 Operación eficiente", "🔵 Baja eficiencia"))))) -> 🟢 Operación eficiente | O39: 0.95681538 | P39: 1.0423 | Q39: 0.67
A40: P130 Chimbote - PVH | B40: P130 Chimbote - PVH | C40: ene | D40: P130 Chimbote - PVHenero | E40: 305489.76 | F40: 5536704.3 | G40: 18.124026 | H40: 289190.17 | I40: 1.0563629 | J40: 289267.73 | K40: 0.8982 | L40: 1.37 | M40: 🟠 Sobredotada | O40: 1.1388263 | P40: 1.0156 | Q40: 1.19
...
